2022-07-08 15:24:24,577 INFO    MainThread:1789817 [internal.py:wandb_internal():90] W&B internal server running at pid: 1789817, started at: 2022-07-08 15:24:24.576445
2022-07-08 15:24:24,579 INFO    WriterThread:1789817 [datastore.py:open_for_write():75] open: /home/abass.abdulsalam/Documents/works/one_patch_DE/wandb/run-20220708_152422-2dz1yd1w/run-2dz1yd1w.wandb
2022-07-08 15:24:24,583 DEBUG   SenderThread:1789817 [sender.py:send():232] send: header
2022-07-08 15:24:24,584 DEBUG   SenderThread:1789817 [sender.py:send():232] send: run
2022-07-08 15:24:52,665 DEBUG   HandlerThread:1789817 [handler.py:handle_request():141] handle_request: shutdown
2022-07-08 15:24:52,666 INFO    HandlerThread:1789817 [handler.py:finish():806] shutting down handler
2022-07-08 15:24:53,587 INFO    WriterThread:1789817 [datastore.py:close():279] close: /home/abass.abdulsalam/Documents/works/one_patch_DE/wandb/run-20220708_152422-2dz1yd1w/run-2dz1yd1w.wandb
2022-07-08 15:24:54,503 ERROR   SenderThread:1789817 [internal_api.py:execute():143] 409 response executing GraphQL.
2022-07-08 15:24:54,503 ERROR   SenderThread:1789817 [internal_api.py:execute():144] {"errors":[{"message":"Error 1062: Duplicate entry '1113538-2dz1yd1w' for key 'PRIMARY'","path":["upsertBucket"]}],"data":{"upsertBucket":null}}
2022-07-08 15:24:54,504 ERROR   MainThread:1789817 [internal.py:wandb_internal():165] Thread SenderThread:
Traceback (most recent call last):
  File "/home/abass.abdulsalam/.conda/envs/thesis/lib/python3.8/site-packages/wandb/apis/normalize.py", line 22, in wrapper
    return func(*args, **kwargs)
  File "/home/abass.abdulsalam/.conda/envs/thesis/lib/python3.8/site-packages/wandb/sdk/internal/internal_api.py", line 1319, in upsert_run
    response = self.gql(mutation, variable_values=variable_values, **kwargs)
  File "/home/abass.abdulsalam/.conda/envs/thesis/lib/python3.8/site-packages/wandb/sdk/lib/retry.py", line 102, in __call__
    result = self._call_fn(*args, **kwargs)
  File "/home/abass.abdulsalam/.conda/envs/thesis/lib/python3.8/site-packages/wandb/sdk/internal/internal_api.py", line 140, in execute
    return self.client.execute(*args, **kwargs)
  File "/home/abass.abdulsalam/.conda/envs/thesis/lib/python3.8/site-packages/wandb/vendor/gql-0.2.0/wandb_gql/client.py", line 52, in execute
    result = self._get_result(document, *args, **kwargs)
  File "/home/abass.abdulsalam/.conda/envs/thesis/lib/python3.8/site-packages/wandb/vendor/gql-0.2.0/wandb_gql/client.py", line 60, in _get_result
    return self.transport.execute(document, *args, **kwargs)
  File "/home/abass.abdulsalam/.conda/envs/thesis/lib/python3.8/site-packages/wandb/vendor/gql-0.2.0/wandb_gql/transport/requests.py", line 39, in execute
    request.raise_for_status()
  File "/home/abass.abdulsalam/.conda/envs/thesis/lib/python3.8/site-packages/requests/models.py", line 960, in raise_for_status
    raise HTTPError(http_error_msg, response=self)
requests.exceptions.HTTPError: 409 Client Error: Conflict for url: https://api.wandb.ai/graphql

During handling of the above exception, another exception occurred:

Traceback (most recent call last):
  File "/home/abass.abdulsalam/.conda/envs/thesis/lib/python3.8/site-packages/wandb/sdk/internal/internal_util.py", line 51, in run
    self._run()
  File "/home/abass.abdulsalam/.conda/envs/thesis/lib/python3.8/site-packages/wandb/sdk/internal/internal_util.py", line 102, in _run
    self._process(record)
  File "/home/abass.abdulsalam/.conda/envs/thesis/lib/python3.8/site-packages/wandb/sdk/internal/internal.py", line 310, in _process
    self._sm.send(record)
  File "/home/abass.abdulsalam/.conda/envs/thesis/lib/python3.8/site-packages/wandb/sdk/internal/sender.py", line 234, in send
    send_handler(record)
  File "/home/abass.abdulsalam/.conda/envs/thesis/lib/python3.8/site-packages/wandb/sdk/internal/sender.py", line 692, in send_run
    self._init_run(run, config_value_dict)
  File "/home/abass.abdulsalam/.conda/envs/thesis/lib/python3.8/site-packages/wandb/sdk/internal/sender.py", line 716, in _init_run
    server_run, inserted = self._api.upsert_run(
  File "/home/abass.abdulsalam/.conda/envs/thesis/lib/python3.8/site-packages/wandb/apis/normalize.py", line 24, in wrapper
    raise CommError(err.response, err)
wandb.errors.CommError: <Response [409]>
2022-07-08 15:24:56,697 INFO    MainThread:1789817 [internal.py:handle_exit():80] Internal process exited
